<?xml version="1.0"?>
<robot xmlns:xacro="http://www.ros.org/wiki/xacro" >

    <xacro:include filename="inertial_macros.xacro"/>

    <!-- <xacro:property name="chassis_width" value="0.265"/>
    <xacro:property name="chassis_height" value="0.138"/>
    <xacro:property name="chassis_mass" value="1.0"/>
    <xacro:property name="wheel_radius" value="0.033"/>
    <xacro:property name="wheel_thickness" value="0.026"/>
    <xacro:property name="wheel_mass" value="0.05"/>
    <xacro:property name="wheel_offset_x" value="0.226"/>
    <xacro:property name="wheel_offset_y" value="0.1485"/>
    <xacro:property name="wheel_offset_z" value="0.01"/>
    <xacro:property name="caster_wheel_radius" value="0.01"/>
    <xacro:property name="caster_wheel_mass" value="0.01"/>
    <xacro:property name="caster_wheel_offset_x" value="0.075"/>
    <xacro:property name="caster_wheel_offset_z"> -->

    <material name="white">
        <color rgba="1 1 1 1" />
    </material>
    <material name="orange">
        <color rgba="1 0.3 0.1 1"/>
    </material>
    <material name="blue">
        <color rgba="0.2 0.2 1 1"/>
    </material>
    <material name="black">
        <color rgba="0 0 0 1"/>
    </material>
    <material name="red">
        <color rgba="1 0 0 1"/>
    </material>

    <!-- ======= Base link ======= -->
    <link name="base_link"/>
    <joint name="base_footprint_joint" type="fixed">
        <parent link="base_link"/>
        <child link="base_footprint"/>
        <origin xyz="0 0 0" rpy="0 0 0"/>
    </joint>
    <link name="base_footprint"/>

    <!-- ======= Chassis ======= -->
    <joint name="chassis_joint" type="fixed">
        <parent link="base_link"/>
        <child link="chassis"/>
        <origin xyz="0 0 0"/>
    </joint>
    <link name="chassis">
        <visual>
            <origin xyz="0 0 0.03"/>
            <geometry>
                <box size="0.2 0.1 0.08"/>
            </geometry>
            <material name="orange"/>
        </visual>
        <collision>
            <origin xyz="0 0 0.03"/>
            <geometry>
                <box size="0.2 0.1 0.08"/>
            </geometry>
        </collision>
        <inertial>
            <mass value="10"/> <!-- 任意合理質量 -->
            <inertia ixx="1" ixy="0" ixz="0" iyy="1" iyz="0" izz="1"/>
            <origin xyz="0 0 0" rpy="0 0 0"/>
        </inertial>
    </link>
    <gazebo reference="chassis">
        <material>Gazebo/Orange</material>
    </gazebo>

    <!-- ======= front_Left Wheel ======= -->
    <joint name="front_left_wheel_joint" type="continuous">
        <parent link="base_link"/>
        <child link="front_left_wheel"/>
        <origin xyz="0.05 0.06 0" rpy="-${pi/2} 0 0"/>
        <axis xyz="0 0 1"/>
    </joint>
    <link name="front_left_wheel">
        <visual>
            <geometry>
                <cylinder radius="0.03" length="0.02"/>
            </geometry>
            <material name="blue"/>
        </visual>
        <collision>
            <geometry>
                <sphere radius="0.03"/>
            </geometry>
        </collision>
        <xacro:inertial_cylinder mass="0.05" length="0.02" radius="0.03">
            <origin xyz="0 0 0" rpy="0 0 0"/>
        </xacro:inertial_cylinder>
    </link>
    <gazebo reference="front_left_wheel">
        <material>Gazebo/Blue</material>
    </gazebo>

    <!-- ======= front_Right Wheel ======= -->
    <joint name="front_right_wheel_joint" type="continuous">
        <parent link="base_link"/>
        <child link="front_right_wheel"/>
        <origin xyz="0.05 -0.06 0" rpy="${pi/2} 0 0"/>
        <axis xyz="0 0 -1"/>
    </joint>
    <link name="front_right_wheel">
        <visual>
            <geometry>
                <cylinder radius="0.03" length="0.02"/>
            </geometry>
            <material name="blue"/>
        </visual>
        <collision>
            <geometry>
                <sphere radius="0.03"/>
            </geometry>
        </collision>
        <xacro:inertial_cylinder mass="0.05" length="0.02" radius="0.03">
            <origin xyz="0 0 0" rpy="0 0 0"/>
        </xacro:inertial_cylinder>
    </link>
    <gazebo reference="front_right_wheel">
        <material>Gazebo/Blue</material>
    </gazebo>

    <!-- ======= back_Right Wheel ======= -->
    <joint name="back_right_wheel_joint" type="continuous">
        <parent link="base_link"/>
        <child link="back_right_wheel"/>
        <origin xyz="-0.05 -0.06 0" rpy="${pi/2} 0 0"/>
        <axis xyz="0 0 -1"/>
    </joint>
    <link name="back_right_wheel">
        <visual>
            <geometry>
                <cylinder radius="0.03" length="0.02"/>
            </geometry>
            <material name="blue"/>
        </visual>
        <collision>
            <geometry>
                <sphere radius="0.03"/>
            </geometry>
        </collision>
        <xacro:inertial_cylinder mass="0.05" length="0.02" radius="0.03">
            <origin xyz="0 0 0" rpy="0 0 0"/>
        </xacro:inertial_cylinder>
    </link>
    <gazebo reference="back_right_wheel">
        <material>Gazebo/Blue</material>
    </gazebo>

    <!-- ======= back_Left Wheel ======= -->
    <joint name="back_left_wheel_joint" type="continuous">
        <parent link="base_link"/>
        <child link="back_left_wheel"/>
        <origin xyz="-0.05 0.06 0" rpy="-${pi/2} 0 0"/>
        <axis xyz="0 0 1"/>
    </joint>
    <link name="back_left_wheel">
        <visual>
            <geometry>
                <cylinder radius="0.03" length="0.02"/>
            </geometry>
            <material name="blue"/>
        </visual>
        <collision>
            <geometry>
                <sphere radius="0.03"/>
            </geometry>
        </collision>
        <xacro:inertial_cylinder mass="0.05" length="0.02" radius="0.03">
            <origin xyz="0 0 0" rpy="0 0 0"/>
        </xacro:inertial_cylinder>
    </link>
    <gazebo reference="back_left_wheel">
        <material>Gazebo/Blue</material>
    </gazebo>


    <!-- ======= Caster Wheel ======= -->
    <!-- <joint name="caster_wheel_joint" type="fixed">
        <parent link="chassis"/>
        <child link="caster_wheel"/>
        <origin xyz="-0.075 0 -0.013"/>
    </joint>
    <link name="caster_wheel">
        <visual>
            <geometry>
                <sphere radius="0.017"/>
            </geometry>
            <material name="white"/>
        </visual>
        <collision>
            <geometry>
                <sphere radius="0.017"/>
            </geometry>
        </collision>
        <xacro:inertial_sphere mass="0.01" radius="0.017">
            <origin xyz="0 0 0" rpy="0 0 0"/>
        </xacro:inertial_sphere>
    </link>
    <gazebo reference="caster_wheel">
        <material>Gazebo/White</material>
        <mu1 value="0.001"/>
        <mu2 value="0.001"/>
    </gazebo> -->

</robot>
