<?xml version="1.0" ?>
<!-- Generated using onshape-to-robot -->
<!-- Onshape document_id: 983e3dbf6acfddfcb7d2d900 -->
<robot name="try_gazebo">
  <!-- Link part_1 -->
  <link name="part_1">
    <inertial>
      <origin xyz="-0.0111542 0.00382259 -0.0104117" rpy="0 0 0"/>
      <mass value="0.297509"/>
      <inertia ixx="0.00106713" ixy="0" ixz="0" iyy="0.000476515" iyz="0" izz="0.0015432"/>
    </inertial>
    <!-- Part mc520电机模型1024线 -->
    <visual>
      <origin xyz="-0.0704542 0.0588226 -0.0389117" rpy="-1.5708 -0 -0"/>
      <geometry>
        <mesh filename="package://esp32_receiver/urdf_data/assets/mc520电机模型1024线.stl"/>
      </geometry>
      <material name="mc520电机模型1024线_material">
        <color rgba="1 1 1 1"/>
      </material>
    </visual>
    <collision>
      <origin xyz="-0.0704542 0.0588226 -0.0389117" rpy="-1.5708 -0 -0"/>
      <geometry>
        <mesh filename="package://esp32_receiver/urdf_data/assets/mc520电机模型1024线.stl"/>
      </geometry>
    </collision>
    <!-- Part part_1 -->
    <visual>
      <origin xyz="-0.0111542 0.00382259 -0.0119117" rpy="0 -0 0"/>
      <geometry>
        <mesh filename="package://esp32_receiver/urdf_data/assets/part_1.stl"/>
      </geometry>
      <material name="part_1_material">
        <color rgba="0.615686 0.811765 0.929412 1"/>
      </material>
    </visual>
    <collision>
      <origin xyz="-0.0111542 0.00382259 -0.0119117" rpy="0 -0 0"/>
      <geometry>
        <mesh filename="package://esp32_receiver/urdf_data/assets/part_1.stl"/>
      </geometry>
    </collision>
    <!-- Part mg513µç_úö_¼ü -->
    <visual>
      <origin xyz="-0.0509542 -0.0511774 -0.0119117" rpy="3.14159 -0 -1.5708"/>
      <geometry>
        <mesh filename="package://esp32_receiver/urdf_data/assets/mg513µç_úö_¼ü.stl"/>
      </geometry>
      <material name="mg513µç_úö_¼ü_material">
        <color rgba="0.745098 0.901961 0.960784 1"/>
      </material>
    </visual>
    <collision>
      <origin xyz="-0.0509542 -0.0511774 -0.0119117" rpy="3.14159 -0 -1.5708"/>
      <geometry>
        <mesh filename="package://esp32_receiver/urdf_data/assets/mg513µç_úö_¼ü.stl"/>
      </geometry>
    </collision>
    <!-- Part mg513µç_úö_¼ü_2 -->
    <visual>
      <origin xyz="0.0286458 0.0588226 -0.0119117" rpy="3.14159 -0 1.5708"/>
      <geometry>
        <mesh filename="package://esp32_receiver/urdf_data/assets/mg513µç_úö_¼ü.stl"/>
      </geometry>
      <material name="mg513µç_úö_¼ü_2_material">
        <color rgba="0.745098 0.901961 0.960784 1"/>
      </material>
    </visual>
    <collision>
      <origin xyz="0.0286458 0.0588226 -0.0119117" rpy="3.14159 -0 1.5708"/>
      <geometry>
        <mesh filename="package://esp32_receiver/urdf_data/assets/mg513µç_úö_¼ü.stl"/>
      </geometry>
    </collision>
    <!-- Part mg513µç_úö_¼ü_3 -->
    <visual>
      <origin xyz="-0.0509542 0.0588226 -0.0119117" rpy="3.14159 -0 -1.5708"/>
      <geometry>
        <mesh filename="package://esp32_receiver/urdf_data/assets/mg513µç_úö_¼ü.stl"/>
      </geometry>
      <material name="mg513µç_úö_¼ü_3_material">
        <color rgba="0.745098 0.901961 0.960784 1"/>
      </material>
    </visual>
    <collision>
      <origin xyz="-0.0509542 0.0588226 -0.0119117" rpy="3.14159 -0 -1.5708"/>
      <geometry>
        <mesh filename="package://esp32_receiver/urdf_data/assets/mg513µç_úö_¼ü.stl"/>
      </geometry>
    </collision>
    <!-- Part mc520电机模型1024线_2 -->
    <visual>
      <origin xyz="-0.0704542 -0.0511774 -0.0389117" rpy="-1.5708 -0 -0"/>
      <geometry>
        <mesh filename="package://esp32_receiver/urdf_data/assets/mc520电机模型1024线.stl"/>
      </geometry>
      <material name="mc520电机模型1024线_2_material">
        <color rgba="1 1 1 1"/>
      </material>
    </visual>
    <collision>
      <origin xyz="-0.0704542 -0.0511774 -0.0389117" rpy="-1.5708 -0 -0"/>
      <geometry>
        <mesh filename="package://esp32_receiver/urdf_data/assets/mc520电机模型1024线.stl"/>
      </geometry>
    </collision>
    <!-- Part mc520电机模型1024线_3 -->
    <visual>
      <origin xyz="0.0481458 0.0588226 -0.0389117" rpy="-1.5708 -0 3.14159"/>
      <geometry>
        <mesh filename="package://esp32_receiver/urdf_data/assets/mc520电机模型1024线.stl"/>
      </geometry>
      <material name="mc520电机模型1024线_3_material">
        <color rgba="1 1 1 1"/>
      </material>
    </visual>
    <collision>
      <origin xyz="0.0481458 0.0588226 -0.0389117" rpy="-1.5708 -0 3.14159"/>
      <geometry>
        <mesh filename="package://esp32_receiver/urdf_data/assets/mc520电机模型1024线.stl"/>
      </geometry>
    </collision>
    <!-- Part mc520电机模型1024线_4 -->
    <visual>
      <origin xyz="0.0481458 -0.0511774 -0.0389117" rpy="-1.5708 -0 3.14159"/>
      <geometry>
        <mesh filename="package://esp32_receiver/urdf_data/assets/mc520电机模型1024线.stl"/>
      </geometry>
      <material name="mc520电机模型1024线_4_material">
        <color rgba="1 1 1 1"/>
      </material>
    </visual>
    <collision>
      <origin xyz="0.0481458 -0.0511774 -0.0389117" rpy="-1.5708 -0 3.14159"/>
      <geometry>
        <mesh filename="package://esp32_receiver/urdf_data/assets/mc520电机模型1024线.stl"/>
      </geometry>
    </collision>
    <!-- Part mg513µç_úö_¼ü_4 -->
    <visual>
      <origin xyz="0.0286458 -0.0511774 -0.0119117" rpy="3.14159 -0 1.5708"/>
      <geometry>
        <mesh filename="package://esp32_receiver/urdf_data/assets/mg513µç_úö_¼ü.stl"/>
      </geometry>
      <material name="mg513µç_úö_¼ü_4_material">
        <color rgba="0.745098 0.901961 0.960784 1"/>
      </material>
    </visual>
    <collision>
      <origin xyz="0.0286458 -0.0511774 -0.0119117" rpy="3.14159 -0 1.5708"/>
      <geometry>
        <mesh filename="package://esp32_receiver/urdf_data/assets/mg513µç_úö_¼ü.stl"/>
      </geometry>
    </collision>
  </link>
  <!-- Link part_1_2 -->
  <link name="part_1_2">
    <inertial>
      <origin xyz="-0 -0 -0.0277088" rpy="0 0 0"/>
      <mass value="0.639004"/>
      <inertia ixx="0.000206984" ixy="0" ixz="0" iyy="0.000206984" iyz="0" izz="0.000311277"/>
    </inertial>
    <!-- Part part_1_2 -->
    <visual>
      <origin xyz="-0 -0 -0.013" rpy="1.5708 -0 3.14159"/>
      <geometry>
        <mesh filename="package://esp32_receiver/urdf_data/assets/part_1__2.stl"/>
      </geometry>
      <material name="part_1_2_material">
        <color rgba="0.615686 0.811765 0.929412 1"/>
      </material>
    </visual>
    <collision>
      <origin xyz="-0 -0 -0.013" rpy="1.5708 -0 3.14159"/>
      <geometry>
        <mesh filename="package://esp32_receiver/urdf_data/assets/part_1__2.stl"/>
      </geometry>
    </collision>
  </link>
  <!-- Joint from part_1 to part_1_2 -->
  <joint name="wheel_back_right" type="continuous">
    <origin xyz="0.0564458 -0.0511774 -0.0459117" rpy="-3.14159 1.5708 0"/>
    <parent link="part_1"/>
    <child link="part_1_2"/>
    <axis xyz="0 0 1"/>
    <limit effort="10" velocity="10"/>
  </joint>
  <!-- Link part_1_3 -->
  <link name="part_1_3">
    <inertial>
      <origin xyz="0 -0 -0.0277088" rpy="0 0 0"/>
      <mass value="0.639004"/>
      <inertia ixx="0.000206984" ixy="0" ixz="-0" iyy="0.000206984" iyz="-0" izz="0.000311277"/>
    </inertial>
    <!-- Part part_1_3 -->
    <visual>
      <origin xyz="0 -0 -0.013" rpy="1.5708 -0 -3.14159"/>
      <geometry>
        <mesh filename="package://esp32_receiver/urdf_data/assets/part_1__2.stl"/>
      </geometry>
      <material name="part_1_3_material">
        <color rgba="0.615686 0.811765 0.929412 1"/>
      </material>
    </visual>
    <collision>
      <origin xyz="0 -0 -0.013" rpy="1.5708 -0 -3.14159"/>
      <geometry>
        <mesh filename="package://esp32_receiver/urdf_data/assets/part_1__2.stl"/>
      </geometry>
    </collision>
  </link>
  <!-- Joint from part_1 to part_1_3 -->
  <joint name="wheel_front_right" type="continuous">
    <origin xyz="0.0564458 0.0588226 -0.0459117" rpy="-3.14159 1.5708 0"/>
    <parent link="part_1"/>
    <child link="part_1_3"/>
    <axis xyz="0 0 1"/>
    <limit effort="10" velocity="10"/>
  </joint>
  <!-- Link part_1_4 -->
  <link name="part_1_4">
    <inertial>
      <origin xyz="-0 0 -0.0277088" rpy="0 0 0"/>
      <mass value="0.639004"/>
      <inertia ixx="0.000206984" ixy="0" ixz="0" iyy="0.000206984" iyz="0" izz="0.000311277"/>
    </inertial>
    <!-- Part part_1_4 -->
    <visual>
      <origin xyz="0 0 -0.013" rpy="1.5708 -0 -3.14159"/>
      <geometry>
        <mesh filename="package://esp32_receiver/urdf_data/assets/part_1__2.stl"/>
      </geometry>
      <material name="part_1_4_material">
        <color rgba="0.615686 0.811765 0.929412 1"/>
      </material>
    </visual>
    <collision>
      <origin xyz="0 0 -0.013" rpy="1.5708 -0 -3.14159"/>
      <geometry>
        <mesh filename="package://esp32_receiver/urdf_data/assets/part_1__2.stl"/>
      </geometry>
    </collision>
  </link>
  <!-- Joint from part_1 to part_1_4 -->
  <joint name="wheel_front_left" type="continuous">
    <origin xyz="-0.0787542 0.0588226 -0.0459117" rpy="0 1.5708 0"/>
    <parent link="part_1"/>
    <child link="part_1_4"/>
    <axis xyz="0 0 1"/>
    <limit effort="10" velocity="10"/>
  </joint>
  <!-- Link part_1_5 -->
  <link name="part_1_5">
    <inertial>
      <origin xyz="0 -0 -0.0277088" rpy="0 0 0"/>
      <mass value="0.639004"/>
      <inertia ixx="0.000206984" ixy="0" ixz="0" iyy="0.000206984" iyz="-0" izz="0.000311277"/>
    </inertial>
    <!-- Part part_1_5 -->
    <visual>
      <origin xyz="0 0 -0.013" rpy="1.5708 -0 0"/>
      <geometry>
        <mesh filename="package://esp32_receiver/urdf_data/assets/part_1__2.stl"/>
      </geometry>
      <material name="part_1_5_material">
        <color rgba="0.615686 0.811765 0.929412 1"/>
      </material>
    </visual>
    <collision>
      <origin xyz="0 0 -0.013" rpy="1.5708 -0 0"/>
      <geometry>
        <mesh filename="package://esp32_receiver/urdf_data/assets/part_1__2.stl"/>
      </geometry>
    </collision>
  </link>
  <!-- Joint from part_1 to part_1_5 -->
  <joint name="wheel_back_left" type="continuous">
    <origin xyz="-0.0787542 -0.0511774 -0.0459117" rpy="3.14159 -1.5708 0"/>
    <parent link="part_1"/>
    <child link="part_1_5"/>
    <axis xyz="0 0 1"/>
    <limit effort="10" velocity="10"/>
  </joint>
</robot>
